test/testprint.dat
## this unit test file is for functionality of print..
SELL GFD 1500 100 or01
SELL GFD 1500 30 or011
SELL GFD 1500 104 or02
SELL GFD 1400 100 or03
SELL GFD 1400 105 or04
BUY GFD 1100 400 or05
BUY GFD 1200 600 or06
BUY GFD 1100 10 or07
BUY GFD 1200 10 or08
BUY GFD 1300 100 or09
PRINT
